<?xml version="1.0" ?>
<!-- =================================================================================== -->
<!-- |    This document was autogenerated by xacro from /home/perseusdg/Development/colcon_ws/install/kortex_description/share/kortex_description/robots/gen3.xacro | -->
<!-- |    EDITING THIS FILE BY HAND IS NOT RECOMMENDED                                 | -->
<!-- =================================================================================== -->
<robot name="gen3">
  <link name="world"/>
  <joint name="base_joint" type="fixed">
    <origin rpy="0 0 0" xyz="0 0 0"/>
    <parent link="world"/>
    <child link="base_link"/>
  </joint>
  <link name="base_link">
    <inertial>
      <origin rpy="0 0 0" xyz="-0.000648 -0.000166 0.084487"/>
      <mass value="1.697"/>
      <inertia ixx="0.004622" ixy="9E-06" ixz="6E-05" iyy="0.004495" iyz="9E-06" izz="0.002079"/>
    </inertial>
    <visual>
      <origin rpy="0 0 0" xyz="0 0 0"/>
      <geometry>
        <mesh filename="meshes/visual/base_link.glb"/>
      </geometry>
      <material name="">
        <color rgba="0.75294 0.75294 0.75294 1"/>
      </material>
    </visual>
    <collision>
      <origin rpy="0 0 0" xyz="0 0 0"/>
      <geometry>
        <mesh filename="meshes/collision/base_link.obj"/>
      </geometry>
    </collision>
  </link>
  <link name="shoulder_link">
    <inertial>
      <origin rpy="0 0 0" xyz="-2.3E-05 -0.010364 -0.07336"/>
      <mass value="1.377"/>
      <inertia ixx="0.00457" ixy="1E-06" ixz="2E-06" iyy="0.004831" iyz="0.000448" izz="0.001409"/>
    </inertial>
    <visual>
      <origin rpy="0 0 0" xyz="0 0 0"/>
      <geometry>
        <mesh filename="meshes/visual/shoulder_link.glb"/>
      </geometry>
      <material name="">
        <color rgba="0.75294 0.75294 0.75294 1"/>
      </material>
    </visual>
    <collision>
      <origin rpy="0 0 0" xyz="0 0 0"/>
      <geometry>
        <mesh filename="meshes/collision/shoulder_link.obj"/>
      </geometry>
    </collision>
  </link>
  <joint name="joint_1" type="continuous">
    <origin rpy="-3.1416 0.0 0.0" xyz="0 0 0.15643"/>
    <parent link="base_link"/>
    <child link="shoulder_link"/>
    <axis xyz="0 0 1"/>
    <limit effort="39" velocity="1.3963"/>
  </joint>
  <link name="bicep_link">
    <inertial>
      <origin rpy="0 0 0" xyz="3.5E-05 -0.208207 -0.01889"/>
      <mass value="1.262"/>
      <inertia ixx="0.046752" ixy="-9E-06" ixz="0" iyy="0.00085" iyz="-9.8E-05" izz="0.047188"/>
    </inertial>
    <visual>
      <origin rpy="0 0 0" xyz="0 0 0"/>
      <geometry>
        <mesh filename="meshes/visual/bicep_link.glb"/>
      </geometry>
      <material name="">
        <color rgba="0.75294 0.75294 0.75294 1"/>
      </material>
    </visual>
    <collision>
      <origin rpy="0 0 0" xyz="0 0 0"/>
      <geometry>
        <mesh filename="meshes/collision/bicep_link.obj"/>
      </geometry>
    </collision>
  </link>
  <joint name="joint_2" type="revolute">
    <origin rpy="1.5708 0.0 0.0" xyz="0 0.005375 -0.12838"/>
    <parent link="shoulder_link"/>
    <child link="bicep_link"/>
    <axis xyz="0 0 1"/>
    <limit effort="39" lower="-2.24" upper="2.24" velocity="1.3963"/>
  </joint>
  <link name="forearm_link">
    <inertial>
      <origin rpy="0 0 0" xyz="1.8E-05 0.076168 -0.01397"/>
      <mass value="0.93"/>
      <inertia ixx="0.008292" ixy="-1E-06" ixz="0" iyy="0.000628" iyz="0.000432" izz="0.008464"/>
    </inertial>
    <visual>
      <origin rpy="0 0 0" xyz="0 0 0"/>
      <geometry>
        <mesh filename="meshes/visual/forearm_link.glb"/>
      </geometry>
      <material name="">
        <color rgba="0.75294 0.75294 0.75294 1"/>
      </material>
    </visual>
    <collision>
      <origin rpy="0 0 0" xyz="0 0 0"/>
      <geometry>
        <mesh filename="meshes/collision/forearm_link.obj"/>
      </geometry>
    </collision>
  </link>
  <joint name="joint_3" type="revolute">
    <origin rpy="3.1416 0 0" xyz="0 -0.41 0"/>
    <parent link="bicep_link"/>
    <child link="forearm_link"/>
    <axis xyz="0 0 1"/>
    <limit effort="39" lower="-2.57" upper="2.57" velocity="1.3963"/>
  </joint>
  <link name="spherical_wrist_1_link">
    <inertial>
      <origin rpy="0 0 0" xyz="-1E-06 0.008486 -0.062937"/>
      <mass value="0.6781"/>
      <inertia ixx="0.001645" ixy="0" ixz="0" iyy="0.001666" iyz="-0.000234" izz="0.000389"/>
    </inertial>
    <visual>
      <origin rpy="0 0 0" xyz="0 0 0"/>
      <geometry>
        <mesh filename="/meshes/visual/spherical_wrist_1_link.glb"/>
      </geometry>
      <material name="">
        <color rgba="0.75294 0.75294 0.75294 1"/>
      </material>
    </visual>
    <collision>
      <origin rpy="0 0 0" xyz="0 0 0"/>
      <geometry>
        <mesh filename="/meshes/collision/spherical_wrist_1_link.obj"/>
      </geometry>
    </collision>
  </link>
  <joint name="joint_4" type="continuous">
    <origin rpy="1.5708 0.0 0.0" xyz="0 0.20843 -0.006375"/>
    <parent link="forearm_link"/>
    <child link="spherical_wrist_1_link"/>
    <axis xyz="0 0 1"/>
    <limit effort="9" velocity="1.2218"/>
  </joint>
  <link name="spherical_wrist_2_link">
    <inertial>
      <origin rpy="0 0 0" xyz="-1E-06 0.046429 -0.008704"/>
      <mass value="0.678"/>
      <inertia ixx="0.001685" ixy="0" ixz="0" iyy="0.0004" iyz="0.000255" izz="0.001696"/>
    </inertial>
    <visual>
      <origin rpy="0 0 0" xyz="0 0 0"/>
      <geometry>
        <mesh filename="/meshes/visual/spherical_wrist_2_link.glb"/>
      </geometry>
      <material name="">
        <color rgba="0.75294 0.75294 0.75294 1"/>
      </material>
    </visual>
    <collision>
      <origin rpy="0 0 0" xyz="0 0 0"/>
      <geometry>
        <mesh filename="/meshes/collision/spherical_wrist_2_link.obj"/>
      </geometry>
    </collision>
  </link>
  <joint name="joint_5" type="revolute">
    <origin rpy="-1.5708 0.0 0.0" xyz="0 -0.00017505 -0.10593"/>
    <parent link="spherical_wrist_1_link"/>
    <child link="spherical_wrist_2_link"/>
    <axis xyz="0 0 1"/>
    <limit effort="9" lower="-2.09" upper="2.09" velocity="1.2218"/>
  </joint>
  <link name="bracelet_link">
    <inertial>
      <origin rpy="0 0 0" xyz="-9.3E-05 0.000132 -0.022905"/>
      <mass value="0.364"/>
      <inertia ixx="0.000214" ixy="0" ixz="1E-06" iyy="0.000223" iyz="-2E-06" izz="0.00024"/>
    </inertial>
    <visual>
      <origin rpy="0 0 0" xyz="0 0 0"/>
      <geometry>
        <mesh filename="/meshes/visual/bracelet_no_vision_link.glb"/>
      </geometry>
      <material name="">
        <color rgba="0.75294 0.75294 0.75294 1"/>
      </material>
    </visual>
    <collision>
      <origin rpy="0 0 0" xyz="0 0 0"/>
      <geometry>
        <mesh filename="/meshes/collison/bracelet_no_vision_link.obj"/>
      </geometry>
    </collision>
  </link>
  <joint name="joint_6" type="continuous">
    <origin rpy="1.5708 0.0 0.0" xyz="0 0.10593 -0.00017505"/>
    <parent link="spherical_wrist_2_link"/>
    <child link="bracelet_link"/>
    <axis xyz="0 0 1"/>
    <limit effort="9" velocity="1.2218"/>
  </joint>
  <link name="end_effector_link"/>
  <joint name="end_effector" type="fixed">
    <origin rpy="3.14159265358979 1.09937075168372E-32 3.14159265358979" xyz="0 0 -0.0615250000000001"/>
    <parent link="bracelet_link"/>
    <child link="end_effector_link"/>
    <axis xyz="0 0 0"/>
  </joint>
  <link name="tool_frame"/>
  <joint name="tool_frame_joint" type="fixed">
    <origin rpy="0 0 0" xyz="0 0 0"/>
    <parent link="end_effector_link"/>
    <child link="tool_frame"/>
    <axis xyz="0 0 0"/>
  </joint>
</robot>
